#VRML_SIM R2022a utf8
WorldInfo {
}
Viewpoint {
  orientation -0.13366998477065364 -0.06699450802709965 0.9887588538494206 4.061770245255646
  position 2.829479313509466 3.561041395650434 1.4677742617966496
}
TexturedBackground {
}
TexturedBackgroundLight {
}
RectangleArena {
  floorSize 10 10
}
Robot {
  translation 0.9426852543076822 -0.03425425465412169 0.4689307528926183
  rotation 0.21003333302673072 0.09791746101612377 -0.9727785821274223 0.058384449951554826
  children [
    DEF torso_front Shape {
      appearance RoughPolymer {
        baseColor 0 0 0
      }
      geometry Box {
        size 0.4 0.4 0.1
      }
    }
    Solid {
      translation 0.28 0 0.23
      children [
        Shape {
          appearance PBRAppearance {
            metalness 0
          }
          geometry Box {
            size 0.2 0.2 0.2
          }
        }
        Solid {
          translation 0.11 -0.06 0.04
          rotation 0 1 0 1.5708
          children [
            Shape {
              appearance PBRAppearance {
                baseColor 0 0 0
                metalness 0
              }
              geometry Cylinder {
                height 0.05
                radius 0.02
              }
            }
          ]
        }
        Solid {
          translation 0.11 0.04 0.04
          rotation 0 1 0 1.5708
          children [
            Shape {
              appearance PBRAppearance {
                baseColor 0 0 0
                metalness 0
              }
              geometry Cylinder {
                height 0.05
                radius 0.02
              }
            }
            LightSensor {
              name "lightSensor1"
            }
          ]
          name "solid(1)"
        }
      ]
      name "solid(3)"
    }
    Solid {
      translation 0.26044 0 0.0624781
      rotation 0 1 0 2.87979
      children [
        DEF sphere1 Shape {
          appearance PBRAppearance {
            metalness 0
          }
          geometry Sphere {
            radius 0.05
          }
        }
        Solid {
          translation -0.0445145 0 -0.0791461
          rotation 0 -1 0 -0.523595307179586
          children [
            DEF cyl3 Shape {
              appearance PBRAppearance {
                metalness 0
              }
              geometry Cylinder {
                height 0.15
                radius 0.03
              }
            }
          ]
          boundingObject USE cyl3
          physics DEF phy1 Physics {
            mass 1
          }
        }
        Solid {
          translation 0.0534268 0 0.0197829
          rotation 0 1 0 1.30899
          children [
            DEF cyl3 Shape {
              appearance PBRAppearance {
                metalness 0
              }
              geometry Cylinder {
                height 0.15
                radius 0.03
              }
            }
          ]
          name "solid(1)"
          boundingObject USE cyl3
          physics DEF phy1 Physics {
            mass 1
          }
        }
      ]
      name "solid(4)"
      boundingObject USE sphere1
      physics USE phy1
    }
    DEF leg1 HingeJoint {
      jointParameters HingeJointParameters {
        axis 0 1 0
        anchor 0.09 0.2 0
      }
      device [
        RotationalMotor {
          name "front_left"
          maxTorque 150
        }
      ]
      endPoint Solid {
        translation 0.08999999999999997 0.19999999999999998 0
        rotation 0 1 0 0
        children [
          DEF sphere1 Shape {
            appearance PBRAppearance {
              metalness 0
            }
            geometry Sphere {
              radius 0.05
            }
          }
          Solid {
            translation -0.0645145 0 -0.113787
            rotation 0 -1 0 -0.523595307179586
            children [
              DEF cyl1 Shape {
                appearance PBRAppearance {
                  metalness 0
                }
                geometry Cylinder {
                  height 0.25
                  radius 0.03
                }
              }
              Solid {
                translation 0.01 0 -0.12
                rotation 0 -1 0 1.7016996938995748
                children [
                  DEF sphere1 Shape {
                    appearance PBRAppearance {
                      metalness 0
                    }
                    geometry Sphere {
                      radius 0.05
                    }
                  }
                  Solid {
                    translation -0.0645145 0 -0.113787
                    rotation 0 -1 0 -0.523595307179586
                    children [
                      DEF cyl3 Shape {
                        appearance PBRAppearance {
                          metalness 0
                        }
                        geometry Cylinder {
                          height 0.25
                          radius 0.03
                        }
                      }
                      Solid {
                        translation 0 0 -0.14
                        children [
                          DEF sphere1 Shape {
                            appearance PBRAppearance {
                              metalness 0
                            }
                            geometry Sphere {
                              radius 0.04
                            }
                          }
                        ]
                        boundingObject USE sphere1
                        physics USE phy1
                      }
                    ]
                    boundingObject USE cyl3
                    physics DEF phy1 Physics {
                      mass 1
                    }
                  }
                ]
                name "solid(1)"
                boundingObject USE sphere1
                physics USE phy1
              }
            ]
            boundingObject USE cyl1
            physics USE phy1
          }
        ]
        name "solid(2)"
        boundingObject USE sphere1
        physics USE phy1
      }
    }
    DEF leg2 HingeJoint {
      jointParameters HingeJointParameters {
        position 1.6880938100393188e-05
      }
      device [
        RotationalMotor {
          name "front_right"
        }
      ]
      endPoint Solid {
        translation 0.08999999999999997 -0.19999999997150336 -3.3761876199182867e-06
        rotation 1 0 0 1.6880930919636483e-05
        children [
          DEF sphere1 Shape {
            appearance PBRAppearance {
              metalness 0
            }
            geometry Sphere {
              radius 0.05
            }
          }
          Solid {
            translation -0.0645145 0 -0.113787
            rotation 0 -1 0 -0.523595307179586
            children [
              DEF cyl1 Shape {
                appearance PBRAppearance {
                  metalness 0
                }
                geometry Cylinder {
                  height 0.25
                  radius 0.03
                }
              }
              Solid {
                translation 0.01 0 -0.12
                rotation 0 -1 0 1.7016996938995748
                children [
                  DEF sphere1 Shape {
                    appearance PBRAppearance {
                      metalness 0
                    }
                    geometry Sphere {
                      radius 0.05
                    }
                  }
                  Solid {
                    translation -0.0645145 0 -0.113787
                    rotation 0 -1 0 -0.523595307179586
                    children [
                      DEF cyl3 Shape {
                        appearance PBRAppearance {
                          metalness 0
                        }
                        geometry Cylinder {
                          height 0.25
                          radius 0.03
                        }
                      }
                      Solid {
                        translation 0 0 -0.14
                        children [
                          DEF sphere1 Shape {
                            appearance PBRAppearance {
                              metalness 0
                            }
                            geometry Sphere {
                              radius 0.04
                            }
                          }
                        ]
                        boundingObject USE sphere1
                        physics USE phy1
                      }
                    ]
                    boundingObject USE cyl3
                    physics DEF phy1 Physics {
                      mass 1
                    }
                  }
                ]
                name "solid(1)"
                boundingObject USE sphere1
                physics USE phy1
              }
            ]
            boundingObject USE cyl1
            physics USE phy1
          }
        ]
        name "solid(1)"
        boundingObject USE sphere1
        physics USE phy1
        linearVelocity 4.336629366935402e-06 5.621328814151745e-06 -1.4494901069941521e-07
        angularVelocity -3.0108070127038173e-05 -5.898845747516613e-06 6.856049758371145e-05
      }
    }
    DEF torso HingeJoint {
      jointParameters HingeJointParameters {
        position 1.1795425852640062e-05
        axis 0 0 1
        anchor -0.23 0 0
        minStop -0.5
        maxStop 0.5
        staticFriction 1
      }
      device [
        RotationalMotor {
          name "torso_joint"
          maxTorque 150
        }
      ]
      endPoint Solid {
        translation -0.2499158691007905 0.006245665448956075 5.335420000000004e-07
        rotation -0.8472616010012629 0.5304308507521472 0.028122802832045147 5.029280316382015e-05
        children [
          DEF torso_joint Shape {
            appearance PBRAppearance {
              metalness 0
            }
            geometry Cylinder {
              height 0.1
              radius 0.06
            }
          }
          Solid {
            translation -0.15 0 0
            children [
              DEF back Shape {
                appearance RoughPolymer {
                  baseColor 0 0 0
                }
                geometry Box {
                  size 0.2 0.4 0.1
                }
              }
              DEF leg3 HingeJoint {
                jointParameters HingeJointParameters {
                  position -0.00681982029955844
                }
                device [
                  RotationalMotor {
                    name "back_left"
                  }
                ]
                endPoint Solid {
                  translation 0.0004495357276132759 0.1999340794382579 -0.010347861024208647
                  rotation -1 0 0 0.0068198202995339045
                  children [
                    DEF sphere1 Shape {
                      appearance PBRAppearance {
                        metalness 0
                      }
                      geometry Sphere {
                        radius 0.05
                      }
                    }
                    Solid {
                      translation -0.0645145 0 -0.113787
                      rotation 0 -1 0 -0.523595307179586
                      children [
                        DEF cyl1 Shape {
                          appearance PBRAppearance {
                            metalness 0
                          }
                          geometry Cylinder {
                            height 0.25
                            radius 0.03
                          }
                        }
                        Solid {
                          translation 0.01 0 -0.12
                          rotation 0 -1 0 1.7016996938995748
                          children [
                            DEF sphere1 Shape {
                              appearance PBRAppearance {
                                metalness 0
                              }
                              geometry Sphere {
                                radius 0.05
                              }
                            }
                            Solid {
                              translation -0.0645145 0 -0.113787
                              rotation 0 -1 0 -0.523595307179586
                              children [
                                DEF cyl3 Shape {
                                  appearance PBRAppearance {
                                    metalness 0
                                  }
                                  geometry Cylinder {
                                    height 0.25
                                    radius 0.03
                                  }
                                }
                                Solid {
                                  translation 0 0 -0.14
                                  children [
                                    DEF sphere1 Shape {
                                      appearance PBRAppearance {
                                        metalness 0
                                      }
                                      geometry Sphere {
                                        radius 0.04
                                      }
                                    }
                                  ]
                                  boundingObject USE sphere1
                                  physics USE phy1
                                }
                              ]
                              boundingObject USE cyl3
                              physics DEF phy1 Physics {
                                mass 1
                              }
                            }
                          ]
                          name "solid(1)"
                          boundingObject USE sphere1
                          physics USE phy1
                        }
                      ]
                      boundingObject USE cyl1
                      physics USE phy1
                    }
                  ]
                  name "solid(1)"
                  boundingObject USE sphere1
                  physics USE phy1
                  linearVelocity 1.669748311008926e-06 1.160810485978255e-06 -5.311506702387795e-08
                  angularVelocity 5.639566209206591e-05 -1.0578600851021067e-05 -4.216867118099412e-05
                }
              }
              DEF leg4 HingeJoint {
                jointParameters HingeJointParameters {
                  position 0.007759831044588317
                }
                device [
                  RotationalMotor {
                    name "back_right"
                  }
                ]
                endPoint Solid {
                  translation 0 -0.19999397853243125 -0.001551950633696077
                  rotation 0.9999999999999999 0 0 0.007759831044612917
                  children [
                    DEF sphere1 Shape {
                      appearance PBRAppearance {
                        metalness 0
                      }
                      geometry Sphere {
                        radius 0.05
                      }
                    }
                    Solid {
                      translation -0.0645145 0 -0.113787
                      rotation 0 -1 0 -0.523595307179586
                      children [
                        DEF cyl1 Shape {
                          appearance PBRAppearance {
                            metalness 0
                          }
                          geometry Cylinder {
                            height 0.25
                            radius 0.03
                          }
                        }
                        Solid {
                          translation 0.01 0 -0.12
                          rotation 0 -1 0 1.7016996938995748
                          children [
                            DEF sphere1 Shape {
                              appearance PBRAppearance {
                                metalness 0
                              }
                              geometry Sphere {
                                radius 0.05
                              }
                            }
                            Solid {
                              translation -0.0645145 0 -0.113787
                              rotation 0 -1 0 -0.523595307179586
                              children [
                                DEF cyl3 Shape {
                                  appearance PBRAppearance {
                                    metalness 0
                                  }
                                  geometry Cylinder {
                                    height 0.25
                                    radius 0.03
                                  }
                                }
                                Solid {
                                  translation 0 0 -0.14
                                  children [
                                    DEF sphere1 Shape {
                                      appearance PBRAppearance {
                                        metalness 0
                                      }
                                      geometry Sphere {
                                        radius 0.04
                                      }
                                    }
                                  ]
                                  boundingObject USE sphere1
                                  physics USE phy1
                                }
                              ]
                              boundingObject USE cyl3
                              physics DEF phy1 Physics {
                                mass 1
                              }
                            }
                          ]
                          name "solid(1)"
                          boundingObject USE sphere1
                          physics USE phy1
                        }
                      ]
                      boundingObject USE cyl1
                      physics USE phy1
                    }
                  ]
                  name "solid(2)"
                  boundingObject USE sphere1
                  physics USE phy1
                  linearVelocity -6.18391849805284e-06 4.41477103516956e-06 -2.9985545551919605e-06
                  angularVelocity -4.4208080272300764e-05 -8.518322455540858e-06 -4.034511297144461e-05
                }
              }
            ]
            boundingObject USE back
            physics USE phy1
          }
        ]
        boundingObject USE torso_joint
        physics USE phy1
        linearVelocity -4.810835788508135e-06 -2.0698700547497007e-06 -1.0442888982485103e-05
        angularVelocity -0.0001027306504134589 -3.420453962241961e-06 -4.1278691255038826e-05
      }
    }
  ]
  boundingObject USE torso_front
  physics USE phy1
  controller ""
  linearVelocity -3.541402699901613e-06 3.1761062664226526e-05 -4.235745537129943e-06
  angularVelocity -0.00010093989862371026 -4.986724510486444e-06 7.072812724999073e-05
}
